Traceback (most recent call last):
  File "/usr/local/lib/python3.9/site-packages/jupyter_cache/executors/utils.py", line 51, in single_nb_execution
    executenb(
  File "/usr/local/lib/python3.9/site-packages/nbclient/client.py", line 1204, in execute
    return NotebookClient(nb=nb, resources=resources, km=km, **kwargs).execute()
  File "/usr/local/lib/python3.9/site-packages/nbclient/util.py", line 84, in wrapped
    return just_run(coro(*args, **kwargs))
  File "/usr/local/lib/python3.9/site-packages/nbclient/util.py", line 62, in just_run
    return loop.run_until_complete(coro)
  File "/usr/local/Cellar/python@3.9/3.9.10/Frameworks/Python.framework/Versions/3.9/lib/python3.9/asyncio/base_events.py", line 642, in run_until_complete
    return future.result()
  File "/usr/local/lib/python3.9/site-packages/nbclient/client.py", line 663, in async_execute
    await self.async_execute_cell(
  File "/usr/local/lib/python3.9/site-packages/nbclient/client.py", line 965, in async_execute_cell
    await self._check_raise_for_error(cell, cell_index, exec_reply)
  File "/usr/local/lib/python3.9/site-packages/nbclient/client.py", line 862, in _check_raise_for_error
    raise CellExecutionError.from_cell_and_msg(cell, exec_reply_content)
nbclient.exceptions.CellExecutionError: An error occurred while executing the following cell:
------------------
import os
import json
import pandas as pd
import numpy as np
import re
import nltk
from nltk.corpus import wordnet
from nltk.stem import WordNetLemmatizer 
from nltk.tokenize import word_tokenize
from nltk.corpus import stopwords
import bertopic
import matplotlib.pyplot as plt

import importlib
import std_func
importlib.reload(std_func)
# nltk.download('stopwords')
# nltk.download('wordnet')
------------------

[0;31m---------------------------------------------------------------------------[0m
[0;31mImportError[0m                               Traceback (most recent call last)
Input [0;32mIn [1][0m, in [0;36m<cell line: 11>[0;34m()[0m
[1;32m      9[0m [38;5;28;01mfrom[39;00m [38;5;21;01mnltk[39;00m[38;5;21;01m.[39;00m[38;5;21;01mtokenize[39;00m [38;5;28;01mimport[39;00m word_tokenize
[1;32m     10[0m [38;5;28;01mfrom[39;00m [38;5;21;01mnltk[39;00m[38;5;21;01m.[39;00m[38;5;21;01mcorpus[39;00m [38;5;28;01mimport[39;00m stopwords
[0;32m---> 11[0m [38;5;28;01mimport[39;00m [38;5;21;01mbertopic[39;00m
[1;32m     12[0m [38;5;28;01mimport[39;00m [38;5;21;01mmatplotlib[39;00m[38;5;21;01m.[39;00m[38;5;21;01mpyplot[39;00m [38;5;28;01mas[39;00m [38;5;21;01mplt[39;00m
[1;32m     14[0m [38;5;28;01mimport[39;00m [38;5;21;01mimportlib[39;00m

File [0;32m~/Library/Python/3.9/lib/python/site-packages/bertopic/__init__.py:1[0m, in [0;36m<module>[0;34m[0m
[0;32m----> 1[0m [38;5;28;01mfrom[39;00m [38;5;21;01mbertopic[39;00m[38;5;21;01m.[39;00m[38;5;21;01m_bertopic[39;00m [38;5;28;01mimport[39;00m BERTopic
[1;32m      3[0m __version__ [38;5;241m=[39m [38;5;124m"[39m[38;5;124m0.9.4[39m[38;5;124m"[39m
[1;32m      5[0m __all__ [38;5;241m=[39m [
[1;32m      6[0m     [38;5;124m"[39m[38;5;124mBERTopic[39m[38;5;124m"[39m,
[1;32m      7[0m ]

File [0;32m~/Library/Python/3.9/lib/python/site-packages/bertopic/_bertopic.py:22[0m, in [0;36m<module>[0;34m[0m
[1;32m     20[0m [38;5;66;03m# Models[39;00m
[1;32m     21[0m [38;5;28;01mimport[39;00m [38;5;21;01mhdbscan[39;00m
[0;32m---> 22[0m [38;5;28;01mfrom[39;00m [38;5;21;01mumap[39;00m [38;5;28;01mimport[39;00m UMAP
[1;32m     23[0m [38;5;28;01mfrom[39;00m [38;5;21;01msklearn[39;00m[38;5;21;01m.[39;00m[38;5;21;01mfeature_extraction[39;00m[38;5;21;01m.[39;00m[38;5;21;01mtext[39;00m [38;5;28;01mimport[39;00m CountVectorizer
[1;32m     24[0m [38;5;28;01mfrom[39;00m [38;5;21;01msklearn[39;00m[38;5;21;01m.[39;00m[38;5;21;01mmetrics[39;00m[38;5;21;01m.[39;00m[38;5;21;01mpairwise[39;00m [38;5;28;01mimport[39;00m cosine_similarity

[0;31mImportError[0m: cannot import name 'UMAP' from 'umap' (/usr/local/lib/python3.9/site-packages/umap/__init__.py)
ImportError: cannot import name 'UMAP' from 'umap' (/usr/local/lib/python3.9/site-packages/umap/__init__.py)

